Workbook

Sheet Raw_Starbucks
A1: Company | B1: Year | C1: COGS | D1: Revenue | E1: Gross Profit | F1: Operating Income | G1: Net Income | H1: Interest Expense | I1: Long-term debt | J1: Current portion of long-term debt | K1: 利息＋本金 | L1: Debt | M1: DA | N1: EBITDA | O1: Equity | P1: CFO | Q1: CapEx
A2: Starbucks | B2: 2025 | C2: 11658.2 | D2: 37184.4 | E2: =D2-C2 -> 25526.2 | F2: 2936.6 | G2: 1856.4 | H2: -542.6 | I2: 14575.9 | J2: 1498.9 | K2: =H2+J2 -> 956.3 | L2: =H2+J2 -> 956.3 | M2: 1684.7 | N2: =F2+M2 -> 4621.3 | O2: -8096.6 | P2: 4747.5 | Q2: -2305.5
B3: 2024 | C3: 11180.6 | D3: 36176.2 | E3: =D3-C3 -> 24995.6 | F3: 5408.8 | G3: 3760.9 | H3: -562 | I3: 14319.5 | J3: 1248.9 | K3: =H3+J3 -> 686.9 | L3: =H3+J3 -> 686.9 | M3: 1512.6 | N3: =F3+M3 -> 6921.4 | O3: -7448.9 | P3: 6095.6 | Q3: -2777.5
B4: 2023 | C4: 11409.1 | D4: 35975.6 | E4: =D4-C4 -> 24566.5 | F4: 5870.8 | G4: 4124.5 | H4: -550.1 | I4: 13547.6 | J4: 1818.6 | K4: =H4+J4 -> 1268.5 | L4: =H4+J4 -> 1268.5 | M4: 1362.6 | N4: =F4+M4 -> 7233.4 | O4: -7994.8 | P4: 6008.7 | Q4: -2333.6
B5: 2022 | C5: 10317.4 | D5: 32250.3 | E5: =D5-C5 -> 21932.9 | F5: 4617.8 | G5: 3281.6 | H5: -482.9 | I5: 13119.9 | J5: 1749 | K5: =H5+J5 -> 1266.1 | L5: =H5+J5 -> 1266.1 | M5: 1447.9 | N5: =F5+M5 -> 6065.7 | O5: -8706.6 | P5: 4397.3 | Q5: -1841.3
B6: 2021 | C6: 8738.7 | D6: 32250.3 | E6: =D6-C6 -> 23511.6 | F6: 4872.1 | G6: 4199.3 | H6: -469.8 | I6: 13616.9 | J6: 998.9 | K6: =H6+J6 -> 529.1 | L6: =H6+J6 -> 529.1 | M6: 1441.7 | N6: =F6+M6 -> 6313.8 | O6: -5321.2 | P6: 5989.1 | Q6: -1470
F9: =F2/H2 -> -5.4120899
A11: Total Debt = Long-term debt + Current portion of long-term debt
A12: COGS=Product and distribution costs 銷貨成本
A13: Gross Profit=Revenue - Product and distribution costs
A14: Net Income=Net earnings attributable to Starbucks
A15: CFO=Net cash provided by operating activities
A16: CapEx=Additions to property, plant and equipment

Sheet Raw_Peloton
A1: Company | B1: Year | C1: COGS | D1: Revenue | E1: Gross Profit | F1: Operating Income | G1: Net Income | H1: Interest Expense | I1: Long-term debt | J1: Current portion of long-term debt | K1: 利息＋本金 | L1: Debt | M1: DA | N1: EBITDA | O1: Equity | P1: CFO | Q1: CapEx
A2: Peloton | B2: 2025 | C2: 1222.5 | D2: 2490.8 | E2: 1268.3 | F2: -36.2 | G2: -118.9 | H2: -134.5 | I2: =B20+D21 -> 1290.5 | J2: 208.5 | K2: =H2+J2 -> 74 | L2: =H2+J2 -> 74 | M2: 89.7 | N2: =F2+M2 -> 53.5 | O2: -413.8 | P2: 333 | Q2: -9.3
B3: 2024 | C3: 1494 | D3: 2700.5 | E3: 1206.5 | F3: -529 | G3: -551.9 | H3: -112.5 | I3: =D20+F21 -> 1490.1 | J3: 10 | K3: =H3+J3 -> -102.5 | L3: =H3+J3 -> -102.5 | M3: 108.8 | N3: =F3+M3 -> -420.2 | O3: -519.1 | P3: -66.1 | Q3: -19.7
B4: 2023 | C4: 1876.7 | D4: 2800.2 | E4: 923.5 | F4: -1197.1 | G4: -1261.7 | H4: -97.1 | I4: =J20+L21 -> 1678.9 | J4: 7.5 | K4: =H4+J4 -> -89.6 | L4: =H4+J4 -> -89.6 | M4: 124.3 | N4: =F4+M4 -> -1072.8 | O4: -295.1 | P4: -387.6 | Q4: -82.4
B5: 2022 | C5: 2883.8 | D5: 3582.1 | E5: 698.4 | F5: -2734 | G5: -2827.7 | H5: -43 | I5: =O20+P21 -> 1554 | J5: 7.5 | K5: =H5+J5 -> -35.5 | L5: =H5+J5 -> -35.5 | M5: 142.8 | N5: =F5+M5 -> -2591.2 | O5: 592.9 | P5: -2020 | Q5: -337.3
E9: 1268.3
E10: 2490.8
A11: COGS=Total cost of revenue | E11: 2700.5
A12: Operating Income=Loss from operations | E12: 1206.5
A13: Net Income=Net loss
A14: Capital expenditures
A15: Convertible senior notes, net of current portion
A20: Convertible senior notes, net of current portion | B20: 343.6 | D20: 540 | H20: 0% Convertible senior notes, net | J20: 988 | O20: 864
A21: Term loan, net of current portion | D21: 946.9 | F21: 950.1 | H21: Term loan, net | L21: 690.9 | P21: 690

Sheet Ratio_Analysis
A1: Profitability | B1: Gross Margin = Gross Profit / Revenue
B2: Operating Margin = Operating Income / Revenue
B3: Net Margin = Net Income / Revenue | H3: Net Margin | J3: FCF | L3: D/E | N3: Coverage
H4: > 10% | I4: 5 | J4: Stable Positive | K4: 5 | L4: < 1 | M4: 5 | N4: > 5 | O4: 5
A5: Cash Flow | B5: FCF = CFO - CapEx | H5: 5% – 10% | I5: 4 | J5: Occasionally Negative | K5: 3 | L5: 1–2 | M5: 4 | N5: 2–5 | O5: 4
B6: FCF Margin = FCF / Revenue | H6: 0 – 5% | I6: 3 | J6: Persistently Negative | K6: 1 | L6: > 2 | M6: 2 | N6: 1–2 | O6: 2
H7: < 0 | I7: 1 | L7: 負 equity | M7: 1 | N7: < 1 | O7: 1
A8: Leverage | B8: Debt to Equity = Total Debt / Equity
A10: Coverage利息保障倍數 | B10: Interest Coverage = Operating Income / Interest Expense
A13: Starbucks | B13: 2025 | C13: 2024 | D13: 2023 | E13: 2022
A14: Gross Margin | B14: =Raw_Starbucks!E2/Raw_Starbucks!D2 -> 0.68647605 | C14: =Raw_Starbucks!E3/Raw_Starbucks!D3 -> 0.69094045 | D14: =Raw_Starbucks!E4/Raw_Starbucks!D4 -> 0.68286561 | E14: =Raw_Starbucks!E5/Raw_Starbucks!D5 -> 0.6800836
A15: Operating Margin | B15: =Raw_Starbucks!F2/Raw_Starbucks!D2 -> 0.078973978 | C15: =Raw_Starbucks!F3/Raw_Starbucks!D3 -> 0.14951266 | D15: =Raw_Starbucks!F4/Raw_Starbucks!D4 -> 0.16318838 | E15: =Raw_Starbucks!F5/Raw_Starbucks!D5 -> 0.14318626
A16: Net Margin | B16: =Raw_Starbucks!G2/Raw_Starbucks!D2 -> 0.049924162 | C16: =Raw_Starbucks!G2/Raw_Starbucks!D2 -> 0.049924162 | D16: =Raw_Starbucks!G4/Raw_Starbucks!D4 -> 0.11464715 | E16: =Raw_Starbucks!G5/Raw_Starbucks!D5 -> 0.10175409
A17: FCF | B17: =Raw_Starbucks!P2-Raw_Starbucks!Q2 -> 7053 | C17: =Raw_Starbucks!P3-Raw_Starbucks!Q3 -> 8873.1 | D17: =Raw_Starbucks!P4-Raw_Starbucks!Q4 -> 8342.3 | E17: =Raw_Starbucks!P5-Raw_Starbucks!Q5 -> 6238.6
A18: FCF Margin | B18: =B17/Raw_Starbucks!D2 -> 0.18967632 | C18: =C17/Raw_Starbucks!D3 -> 0.24527452 | D18: =D17/Raw_Starbucks!D4 -> 0.23188772 | E18: =E17/Raw_Starbucks!D5 -> 0.19344316
A19: Debt / Equity | B19: =Raw_Starbucks!L2/Raw_Starbucks!O2 -> -0.11811131 | C19: =Raw_Starbucks!L3/Raw_Starbucks!O3 -> -0.092214958 | D19: =Raw_Starbucks!L4/Raw_Starbucks!O4 -> -0.15866563 | E19: =Raw_Starbucks!L5/Raw_Starbucks!O5 -> -0.14541842
A20: Debt/EBITDA | B20: =Raw_Starbucks!L2/Raw_Starbucks!N2 -> 0.20693311 | C20: =Raw_Starbucks!L3/Raw_Starbucks!N3 -> 0.099242928 | D20: =Raw_Starbucks!L4/Raw_Starbucks!N4 -> 0.17536705 | E20: =Raw_Starbucks!L5/Raw_Starbucks!N5 -> 0.20873106
A21: DSCR | B21: =Raw_Starbucks!N2/Raw_Starbucks!K2 -> 4.8324793 | C21: =Raw_Starbucks!N3/Raw_Starbucks!K3 -> 10.076285 | D21: =Raw_Starbucks!N4/Raw_Starbucks!K4 -> 5.7023256 | E21: =Raw_Starbucks!N5/Raw_Starbucks!L5 -> 4.7908538
A22: Interest Coverage | B22: =Raw_Starbucks!F2/ABS(Raw_Starbucks!H2) -> 5.4120899 | C22: =Raw_Starbucks!F3/ABS(Raw_Starbucks!H3) -> 9.6241993 | D22: =Raw_Starbucks!F4/ABS(Raw_Starbucks!H4) -> 10.672241 | E22: =Raw_Starbucks!F5/ABS(Raw_Starbucks!H5) -> 9.5626424
A24: Peloton | B24: 2025 | C24: 2024 | D24: 2023 | E24: 2022
A25: Gross Margin | B25: =Raw_Peloton!E2/Raw_Peloton!D2 -> 0.50919383 | C25: =Raw_Peloton!E3/Raw_Peloton!D3 -> 0.44676912 | D25: =Raw_Peloton!E4/Raw_Peloton!D4 -> 0.32979787 | E25: =Raw_Peloton!E5/Raw_Peloton!D5 -> 0.19496943
A26: Operating Margin | B26: =Raw_Peloton!F2/Raw_Peloton!D2 -> -0.014533483 | C26: =Raw_Peloton!F3/Raw_Peloton!D3 -> -0.19588965 | D26: =Raw_Peloton!F4/Raw_Peloton!D4 -> -0.42750518 | E26: =Raw_Peloton!F5/Raw_Peloton!D5 -> -0.76323944
A27: Net Margin | B27: =Raw_Peloton!G2/Raw_Peloton!D2 -> -0.047735667 | C27: =Raw_Peloton!G3/Raw_Peloton!D3 -> -0.20436956 | D27: =Raw_Peloton!G4/Raw_Peloton!D4 -> -0.45057496 | E27: =Raw_Peloton!G5/Raw_Peloton!D5 -> -0.78939728
A28: FCF | B28: =Raw_Peloton!P2-Raw_Peloton!Q2 -> 342.3 | C28: =Raw_Peloton!P3-Raw_Peloton!Q3 -> -46.4 | D28: =Raw_Peloton!P4-Raw_Peloton!Q4 -> -305.2 | E28: =Raw_Peloton!P5-Raw_Peloton!Q5 -> -1682.7
A29: FCF Margin | B29: =Ratio_Analysis!B28/Raw_Peloton!D2 -> 0.13742573 | C29: =C28/Raw_Peloton!D3 -> -0.017182003 | D29: =D28/Raw_Peloton!D4 -> -0.10899221 | E29: =E28/Raw_Peloton!D5 -> -0.46975238
A30: Debt / Equity | B30: =Raw_Peloton!L2/Raw_Peloton!O2 -> -0.17883035 | C30: =Raw_Peloton!L3/Raw_Peloton!O3 -> 0.19745714 | D30: =Raw_Peloton!L4/Raw_Peloton!O4 -> 0.30362589 | E30: =Raw_Peloton!L5/Raw_Peloton!O5 -> -0.05987519
A31: Interest Coverage | B31: =Raw_Peloton!F2/Raw_Peloton!H2 -> 0.26914498 | C31: =Raw_Peloton!F3/Raw_Peloton!H3 -> 4.7022222 | D31: =Raw_Peloton!F4/Raw_Peloton!H4 -> 12.328527 | E31: =Raw_Peloton!F5/Raw_Peloton!H5 -> 63.581395
A32: EBITDA/Debt | B32: =Raw_Peloton!L2/Raw_Peloton!N2 -> 1.3831776 | C32: － | D32: － | E32: -
A33: DSCR | B33: =Raw_Peloton!N2/Raw_Peloton!K2 -> 0.72297297 | D33: (負的沒有參考價值）
A36: Starbucks 長年進行大規模的股票回購（Buybacks）和發放股利，導致其帳面 Equity（股東權益）為負數
A37: 在傳統會計中，負權益代表公司資產不足以抵償負債（技術性資產負債表破產）
A38: 對於這種特殊公司，建議改用 Debt/EBITDA（債務為息稅折舊攤銷前利潤的幾倍）來衡量槓桿，而非 D/E Ratio
A42: Profitability Score =0.4 × Gross Margin+ 0.3 × Operating Margin+ 0.3 × FCF Margin
A44: 2025_Starbucks | B44: =#REF!*0.4+#REF!*0.3+0.3*#REF! -> #REF!
A45: 2024_Starbucks | B45: =#REF!*0.4+#REF!*0.3+#REF!*0.3 -> #REF!
D48: DSCR | E48: >1.5健康
A49: 2023_Starbucks | B49: =0.4*#REF!+0.3*#REF!+0.3*#REF! -> #REF! | E49: <1.0警訊
B50: =AVERAGE(B44:B49) -> #REF!
A53: 2025_Peloton | B53: =0.4*#REF!+0.3*#REF!+0.3*#REF! -> #REF!
A54: 2024_Peloton | B54: =0.4*#REF!+0.3*#REF!+0.3*#REF! -> #REF!
...

Sheet credit score
A1: Starbucks | B1: Category | C1: Score | G1: Category | H1: Score_Starbucks | I1: Score_Peloton | J1: Weight
B2: Profitability | C2: 4 | G2: Profitability | H2: 4 | I2: 1 | J2: 0.3
B3: Cash Flow | C3: 5 | G3: Cash Flow | H3: 5 | I3: 2 | J3: 0.25
B4: Leverage | C4: 4 | G4: Leverage | H4: 4 | I4: 1 | J4: 0.2
B5: Coverage | C5: 5 | G5: Coverage | H5: 5 | I5: 2 | J5: 0.25
A6: Peloton | B6: Category | C6: Score | G6: Total | H6: =SUMPRODUCT(H2:H5,J2:J5) -> 4.5 | I6: =SUMPRODUCT(I2:I5,J2:J5) -> 1.5
B7: Profitability | C7: 1 | I7: Watch List or Classified Assets
B8: Cash Flow | C8: 2
B9: Leverage | C9: 1
B10: Coverage | C10: 2
A13: Category | B13: Weight | G13: Profitability Score =0.4 × Gross Margin+ 0.3 × Operating Margin+ 0.3 × FCF Margin
A14: Profitability | B14: 0.15
A15: Cash Flow | B15: 0.35
A16: Leverage | B16: 0.15
A17: Coverage | B17: 0.35
A19: Cash Flow（現金流）」與「Coverage（償債能力）」通常比獲利更重要。
A20: 獲利（Net Income）可以透過會計手段調整，但現金流（FCF）才是還款的真實來源。
A21: Ｓ＆Ｐ
A22: Cash Flow,Coverage才是還錢的主要指標
A23: Profitability,Leverage是輔助指標
